{"modules": [{"testcases": [{"error": {"message": "WebDriverException: Message: 'chrome' executable may have wrong permissions. Please see https://sites.google.com/a/chromium.org/chromedriver/home", "traceback": [{"linenr": 329, "function": "run", "line": "testMethod()", "filename": "C:\\Python27\\lib\\unittest\\case.py"}, {"linenr": 146, "function": "wrapper", "line": "return func(self, *args, **kwargs)", "filename": "C:\\Python27\\lib\\site-packages\\ddt.py"}, {"linenr": 32, "function": "test_login_password_ok", "line": "self.driver = self.setBrowser(browser_type)", "filename": "D:\\Dropbox\\Dropbox\\positivo_selenium\\sanity_test\\test_login.py"}, {"linenr": 31, "function": "setBrowser", "line": "service.start()", "filename": "D:\\Dropbox\\Dropbox\\positivo_selenium\\classes\\common_functions.py"}, {"linenr": 78, "function": "start", "line": "os.path.basename(self.path), docs_msg)", "filename": "C:\\Python27\\lib\\site-packages\\selenium\\webdriver\\chrome\\service.py"}]}, "result": "error", "name": "test_login_password_ok_10___PA_14____login_senior_tester_chrome____luis____luis123____senior_tester____CHROME__"}, {"error": {"message": "URLError: <urlopen error [Errno 10061] No connection could be made because the target machine actively refused it>\n-------------------- >> begin captured logging << --------------------\nselenium.webdriver.remote.remote_connection: DEBUG: POST http://192.168.100.2:5556/wd/hub/session {\"desiredCapabilities\": {\"platform\": \"WINDOWS\", \"browserName\": \"internet explorer\", \"version\": \"\", \"javascriptEnabled\": true}}\n--------------------- >> end captured logging << ---------------------", "traceback": [{"linenr": 329, "function": "run", "line": "testMethod()", "filename": "C:\\Python27\\lib\\unittest\\case.py"}, {"linenr": 146, "function": "wrapper", "line": "return func(self, *args, **kwargs)", "filename": "C:\\Python27\\lib\\site-packages\\ddt.py"}, {"linenr": 32, "function": "test_login_password_ok", "line": "self.driver = self.setBrowser(browser_type)", "filename": "D:\\Dropbox\\Dropbox\\positivo_selenium\\sanity_test\\test_login.py"}, {"linenr": 40, "function": "setBrowser", "line": "desired_capabilities=DesiredCapabilities.INTERNETEXPLORER)", "filename": "D:\\Dropbox\\Dropbox\\positivo_selenium\\classes\\common_functions.py"}, {"linenr": 87, "function": "__init__", "line": "self.start_session(desired_capabilities, browser_profile)", "filename": "C:\\Python27\\lib\\site-packages\\selenium\\webdriver\\remote\\webdriver.py"}, {"linenr": 136, "function": "start_session", "line": "'desiredCapabilities': desired_capabilities,", "filename": "C:\\Python27\\lib\\site-packages\\selenium\\webdriver\\remote\\webdriver.py"}, {"linenr": 194, "function": "execute", "line": "response = self.command_executor.execute(driver_command, params)", "filename": "C:\\Python27\\lib\\site-packages\\selenium\\webdriver\\remote\\webdriver.py"}, {"linenr": 395, "function": "execute", "line": "return self._request(command_info[0], url, body=data)", "filename": "C:\\Python27\\lib\\site-packages\\selenium\\webdriver\\remote\\remote_connection.py"}, {"linenr": 463, "function": "_request", "line": "resp = opener.open(request, timeout=self._timeout)", "filename": "C:\\Python27\\lib\\site-packages\\selenium\\webdriver\\remote\\remote_connection.py"}, {"linenr": 431, "function": "open", "line": "response = self._open(req, data)", "filename": "C:\\Python27\\lib\\urllib2.py"}, {"linenr": 449, "function": "_open", "line": "'_open', req)", "filename": "C:\\Python27\\lib\\urllib2.py"}, {"linenr": 409, "function": "_call_chain", "line": "result = func(*args)", "filename": "C:\\Python27\\lib\\urllib2.py"}, {"linenr": 1227, "function": "http_open", "line": "return self.do_open(httplib.HTTPConnection, req)", "filename": "C:\\Python27\\lib\\urllib2.py"}, {"linenr": 1197, "function": "do_open", "line": "raise URLError(err)", "filename": "C:\\Python27\\lib\\urllib2.py"}]}, "result": "error", "name": "test_login_password_ok_1___PA_1____login_admin_firefox____admin____admin____admin____IE__"}, {"error": {"message": "WebDriverException: Message: 'chrome' executable may have wrong permissions. Please see https://sites.google.com/a/chromium.org/chromedriver/home", "traceback": [{"linenr": 329, "function": "run", "line": "testMethod()", "filename": "C:\\Python27\\lib\\unittest\\case.py"}, {"linenr": 146, "function": "wrapper", "line": "return func(self, *args, **kwargs)", "filename": "C:\\Python27\\lib\\site-packages\\ddt.py"}, {"linenr": 32, "function": "test_login_password_ok", "line": "self.driver = self.setBrowser(browser_type)", "filename": "D:\\Dropbox\\Dropbox\\positivo_selenium\\sanity_test\\test_login.py"}, {"linenr": 31, "function": "setBrowser", "line": "service.start()", "filename": "D:\\Dropbox\\Dropbox\\positivo_selenium\\classes\\common_functions.py"}, {"linenr": 78, "function": "start", "line": "os.path.basename(self.path), docs_msg)", "filename": "C:\\Python27\\lib\\site-packages\\selenium\\webdriver\\chrome\\service.py"}]}, "result": "error", "name": "test_login_password_ok_2___PA_3____login_admin_chrome____admin____admin____admin____CHROME__"}, {"error": {"message": "WebDriverException: Message: 'chrome' executable may have wrong permissions. Please see https://sites.google.com/a/chromium.org/chromedriver/home", "traceback": [{"linenr": 329, "function": "run", "line": "testMethod()", "filename": "C:\\Python27\\lib\\unittest\\case.py"}, {"linenr": 146, "function": "wrapper", "line": "return func(self, *args, **kwargs)", "filename": "C:\\Python27\\lib\\site-packages\\ddt.py"}, {"linenr": 32, "function": "test_login_password_ok", "line": "self.driver = self.setBrowser(browser_type)", "filename": "D:\\Dropbox\\Dropbox\\positivo_selenium\\sanity_test\\test_login.py"}, {"linenr": 31, "function": "setBrowser", "line": "service.start()", "filename": "D:\\Dropbox\\Dropbox\\positivo_selenium\\classes\\common_functions.py"}, {"linenr": 78, "function": "start", "line": "os.path.basename(self.path), docs_msg)", "filename": "C:\\Python27\\lib\\site-packages\\selenium\\webdriver\\chrome\\service.py"}]}, "result": "error", "name": "test_login_password_ok_3___PA_4____login_guest_chrome____daniel____daniel123____guest____CHROME__"}, {"error": {"message": "WebDriverException: Message: 'chrome' executable may have wrong permissions. Please see https://sites.google.com/a/chromium.org/chromedriver/home", "traceback": [{"linenr": 329, "function": "run", "line": "testMethod()", "filename": "C:\\Python27\\lib\\unittest\\case.py"}, {"linenr": 146, "function": "wrapper", "line": "return func(self, *args, **kwargs)", "filename": "C:\\Python27\\lib\\site-packages\\ddt.py"}, {"linenr": 32, "function": "test_login_password_ok", "line": "self.driver = self.setBrowser(browser_type)", "filename": "D:\\Dropbox\\Dropbox\\positivo_selenium\\sanity_test\\test_login.py"}, {"linenr": 31, "function": "setBrowser", "line": "service.start()", "filename": "D:\\Dropbox\\Dropbox\\positivo_selenium\\classes\\common_functions.py"}, {"linenr": 78, "function": "start", "line": "os.path.basename(self.path), docs_msg)", "filename": "C:\\Python27\\lib\\site-packages\\selenium\\webdriver\\chrome\\service.py"}]}, "result": "error", "name": "test_login_password_ok_4___PA_9____login_leader_chrome____jaque____jaque_2015____leader____CHROME__"}, {"error": {"message": "WebDriverException: Message: 'chrome' executable may have wrong permissions. Please see https://sites.google.com/a/chromium.org/chromedriver/home", "traceback": [{"linenr": 329, "function": "run", "line": "testMethod()", "filename": "C:\\Python27\\lib\\unittest\\case.py"}, {"linenr": 146, "function": "wrapper", "line": "return func(self, *args, **kwargs)", "filename": "C:\\Python27\\lib\\site-packages\\ddt.py"}, {"linenr": 32, "function": "test_login_password_ok", "line": "self.driver = self.setBrowser(browser_type)", "filename": "D:\\Dropbox\\Dropbox\\positivo_selenium\\sanity_test\\test_login.py"}, {"linenr": 31, "function": "setBrowser", "line": "service.start()", "filename": "D:\\Dropbox\\Dropbox\\positivo_selenium\\classes\\common_functions.py"}, {"linenr": 78, "function": "start", "line": "os.path.basename(self.path), docs_msg)", "filename": "C:\\Python27\\lib\\site-packages\\selenium\\webdriver\\chrome\\service.py"}]}, "result": "error", "name": "test_login_password_ok_5___PA_10____login_tester_chrome____alex____test_2015____tester____CHROME__"}, {"error": {"message": "URLError: <urlopen error [Errno 10061] No connection could be made because the target machine actively refused it>\n-------------------- >> begin captured logging << --------------------\nselenium.webdriver.remote.remote_connection: DEBUG: POST http://192.168.100.2:5557/wd/hub/session {\"desiredCapabilities\": {\"platform\": \"ANY\", \"browserName\": \"firefox\", \"version\": \"\", \"marionette\": false, \"javascriptEnabled\": true}}\n--------------------- >> end captured logging << ---------------------", "traceback": [{"linenr": 329, "function": "run", "line": "testMethod()", "filename": "C:\\Python27\\lib\\unittest\\case.py"}, {"linenr": 146, "function": "wrapper", "line": "return func(self, *args, **kwargs)", "filename": "C:\\Python27\\lib\\site-packages\\ddt.py"}, {"linenr": 32, "function": "test_login_password_ok", "line": "self.driver = self.setBrowser(browser_type)", "filename": "D:\\Dropbox\\Dropbox\\positivo_selenium\\sanity_test\\test_login.py"}, {"linenr": 25, "function": "setBrowser", "line": "desired_capabilities=DesiredCapabilities.FIREFOX)", "filename": "D:\\Dropbox\\Dropbox\\positivo_selenium\\classes\\common_functions.py"}, {"linenr": 87, "function": "__init__", "line": "self.start_session(desired_capabilities, browser_profile)", "filename": "C:\\Python27\\lib\\site-packages\\selenium\\webdriver\\remote\\webdriver.py"}, {"linenr": 136, "function": "start_session", "line": "'desiredCapabilities': desired_capabilities,", "filename": "C:\\Python27\\lib\\site-packages\\selenium\\webdriver\\remote\\webdriver.py"}, {"linenr": 194, "function": "execute", "line": "response = self.command_executor.execute(driver_command, params)", "filename": "C:\\Python27\\lib\\site-packages\\selenium\\webdriver\\remote\\webdriver.py"}, {"linenr": 395, "function": "execute", "line": "return self._request(command_info[0], url, body=data)", "filename": "C:\\Python27\\lib\\site-packages\\selenium\\webdriver\\remote\\remote_connection.py"}, {"linenr": 463, "function": "_request", "line": "resp = opener.open(request, timeout=self._timeout)", "filename": "C:\\Python27\\lib\\site-packages\\selenium\\webdriver\\remote\\remote_connection.py"}, {"linenr": 431, "function": "open", "line": "response = self._open(req, data)", "filename": "C:\\Python27\\lib\\urllib2.py"}, {"linenr": 449, "function": "_open", "line": "'_open', req)", "filename": "C:\\Python27\\lib\\urllib2.py"}, {"linenr": 409, "function": "_call_chain", "line": "result = func(*args)", "filename": "C:\\Python27\\lib\\urllib2.py"}, {"linenr": 1227, "function": "http_open", "line": "return self.do_open(httplib.HTTPConnection, req)", "filename": "C:\\Python27\\lib\\urllib2.py"}, {"linenr": 1197, "function": "do_open", "line": "raise URLError(err)", "filename": "C:\\Python27\\lib\\urllib2.py"}]}, "result": "error", "name": "test_login_password_ok_6___PA_6____login_guess_firefox____daniel____daniel123____guest____FIREFOX__"}, {"error": {"message": "URLError: <urlopen error [Errno 10061] No connection could be made because the target machine actively refused it>\n-------------------- >> begin captured logging << --------------------\nselenium.webdriver.remote.remote_connection: DEBUG: POST http://192.168.100.2:5557/wd/hub/session {\"desiredCapabilities\": {\"platform\": \"ANY\", \"browserName\": \"firefox\", \"version\": \"\", \"marionette\": false, \"javascriptEnabled\": true}}\n--------------------- >> end captured logging << ---------------------", "traceback": [{"linenr": 329, "function": "run", "line": "testMethod()", "filename": "C:\\Python27\\lib\\unittest\\case.py"}, {"linenr": 146, "function": "wrapper", "line": "return func(self, *args, **kwargs)", "filename": "C:\\Python27\\lib\\site-packages\\ddt.py"}, {"linenr": 32, "function": "test_login_password_ok", "line": "self.driver = self.setBrowser(browser_type)", "filename": "D:\\Dropbox\\Dropbox\\positivo_selenium\\sanity_test\\test_login.py"}, {"linenr": 25, "function": "setBrowser", "line": "desired_capabilities=DesiredCapabilities.FIREFOX)", "filename": "D:\\Dropbox\\Dropbox\\positivo_selenium\\classes\\common_functions.py"}, {"linenr": 87, "function": "__init__", "line": "self.start_session(desired_capabilities, browser_profile)", "filename": "C:\\Python27\\lib\\site-packages\\selenium\\webdriver\\remote\\webdriver.py"}, {"linenr": 136, "function": "start_session", "line": "'desiredCapabilities': desired_capabilities,", "filename": "C:\\Python27\\lib\\site-packages\\selenium\\webdriver\\remote\\webdriver.py"}, {"linenr": 194, "function": "execute", "line": "response = self.command_executor.execute(driver_command, params)", "filename": "C:\\Python27\\lib\\site-packages\\selenium\\webdriver\\remote\\webdriver.py"}, {"linenr": 395, "function": "execute", "line": "return self._request(command_info[0], url, body=data)", "filename": "C:\\Python27\\lib\\site-packages\\selenium\\webdriver\\remote\\remote_connection.py"}, {"linenr": 463, "function": "_request", "line": "resp = opener.open(request, timeout=self._timeout)", "filename": "C:\\Python27\\lib\\site-packages\\selenium\\webdriver\\remote\\remote_connection.py"}, {"linenr": 431, "function": "open", "line": "response = self._open(req, data)", "filename": "C:\\Python27\\lib\\urllib2.py"}, {"linenr": 449, "function": "_open", "line": "'_open', req)", "filename": "C:\\Python27\\lib\\urllib2.py"}, {"linenr": 409, "function": "_call_chain", "line": "result = func(*args)", "filename": "C:\\Python27\\lib\\urllib2.py"}, {"linenr": 1227, "function": "http_open", "line": "return self.do_open(httplib.HTTPConnection, req)", "filename": "C:\\Python27\\lib\\urllib2.py"}, {"linenr": 1197, "function": "do_open", "line": "raise URLError(err)", "filename": "C:\\Python27\\lib\\urllib2.py"}]}, "result": "error", "name": "test_login_password_ok_7___PA_7____login_leader_firefox____jaque____jaque_2015____leader____FIREFOX__"}, {"error": {"message": "URLError: <urlopen error [Errno 10061] No connection could be made because the target machine actively refused it>\n-------------------- >> begin captured logging << --------------------\nselenium.webdriver.remote.remote_connection: DEBUG: POST http://192.168.100.2:5557/wd/hub/session {\"desiredCapabilities\": {\"platform\": \"ANY\", \"browserName\": \"firefox\", \"version\": \"\", \"marionette\": false, \"javascriptEnabled\": true}}\n--------------------- >> end captured logging << ---------------------", "traceback": [{"linenr": 329, "function": "run", "line": "testMethod()", "filename": "C:\\Python27\\lib\\unittest\\case.py"}, {"linenr": 146, "function": "wrapper", "line": "return func(self, *args, **kwargs)", "filename": "C:\\Python27\\lib\\site-packages\\ddt.py"}, {"linenr": 32, "function": "test_login_password_ok", "line": "self.driver = self.setBrowser(browser_type)", "filename": "D:\\Dropbox\\Dropbox\\positivo_selenium\\sanity_test\\test_login.py"}, {"linenr": 25, "function": "setBrowser", "line": "desired_capabilities=DesiredCapabilities.FIREFOX)", "filename": "D:\\Dropbox\\Dropbox\\positivo_selenium\\classes\\common_functions.py"}, {"linenr": 87, "function": "__init__", "line": "self.start_session(desired_capabilities, browser_profile)", "filename": "C:\\Python27\\lib\\site-packages\\selenium\\webdriver\\remote\\webdriver.py"}, {"linenr": 136, "function": "start_session", "line": "'desiredCapabilities': desired_capabilities,", "filename": "C:\\Python27\\lib\\site-packages\\selenium\\webdriver\\remote\\webdriver.py"}, {"linenr": 194, "function": "execute", "line": "response = self.command_executor.execute(driver_command, params)", "filename": "C:\\Python27\\lib\\site-packages\\selenium\\webdriver\\remote\\webdriver.py"}, {"linenr": 395, "function": "execute", "line": "return self._request(command_info[0], url, body=data)", "filename": "C:\\Python27\\lib\\site-packages\\selenium\\webdriver\\remote\\remote_connection.py"}, {"linenr": 463, "function": "_request", "line": "resp = opener.open(request, timeout=self._timeout)", "filename": "C:\\Python27\\lib\\site-packages\\selenium\\webdriver\\remote\\remote_connection.py"}, {"linenr": 431, "function": "open", "line": "response = self._open(req, data)", "filename": "C:\\Python27\\lib\\urllib2.py"}, {"linenr": 449, "function": "_open", "line": "'_open', req)", "filename": "C:\\Python27\\lib\\urllib2.py"}, {"linenr": 409, "function": "_call_chain", "line": "result = func(*args)", "filename": "C:\\Python27\\lib\\urllib2.py"}, {"linenr": 1227, "function": "http_open", "line": "return self.do_open(httplib.HTTPConnection, req)", "filename": "C:\\Python27\\lib\\urllib2.py"}, {"linenr": 1197, "function": "do_open", "line": "raise URLError(err)", "filename": "C:\\Python27\\lib\\urllib2.py"}]}, "result": "error", "name": "test_login_password_ok_8___PA_12____login_tester_firefox____alex____test_2015____tester____FIREFOX__"}, {"error": {"message": "URLError: <urlopen error [Errno 10061] No connection could be made because the target machine actively refused it>\n-------------------- >> begin captured logging << --------------------\nselenium.webdriver.remote.remote_connection: DEBUG: POST http://192.168.100.2:5557/wd/hub/session {\"desiredCapabilities\": {\"platform\": \"ANY\", \"browserName\": \"firefox\", \"version\": \"\", \"marionette\": false, \"javascriptEnabled\": true}}\n--------------------- >> end captured logging << ---------------------", "traceback": [{"linenr": 329, "function": "run", "line": "testMethod()", "filename": "C:\\Python27\\lib\\unittest\\case.py"}, {"linenr": 146, "function": "wrapper", "line": "return func(self, *args, **kwargs)", "filename": "C:\\Python27\\lib\\site-packages\\ddt.py"}, {"linenr": 32, "function": "test_login_password_ok", "line": "self.driver = self.setBrowser(browser_type)", "filename": "D:\\Dropbox\\Dropbox\\positivo_selenium\\sanity_test\\test_login.py"}, {"linenr": 25, "function": "setBrowser", "line": "desired_capabilities=DesiredCapabilities.FIREFOX)", "filename": "D:\\Dropbox\\Dropbox\\positivo_selenium\\classes\\common_functions.py"}, {"linenr": 87, "function": "__init__", "line": "self.start_session(desired_capabilities, browser_profile)", "filename": "C:\\Python27\\lib\\site-packages\\selenium\\webdriver\\remote\\webdriver.py"}, {"linenr": 136, "function": "start_session", "line": "'desiredCapabilities': desired_capabilities,", "filename": "C:\\Python27\\lib\\site-packages\\selenium\\webdriver\\remote\\webdriver.py"}, {"linenr": 194, "function": "execute", "line": "response = self.command_executor.execute(driver_command, params)", "filename": "C:\\Python27\\lib\\site-packages\\selenium\\webdriver\\remote\\webdriver.py"}, {"linenr": 395, "function": "execute", "line": "return self._request(command_info[0], url, body=data)", "filename": "C:\\Python27\\lib\\site-packages\\selenium\\webdriver\\remote\\remote_connection.py"}, {"linenr": 463, "function": "_request", "line": "resp = opener.open(request, timeout=self._timeout)", "filename": "C:\\Python27\\lib\\site-packages\\selenium\\webdriver\\remote\\remote_connection.py"}, {"linenr": 431, "function": "open", "line": "response = self._open(req, data)", "filename": "C:\\Python27\\lib\\urllib2.py"}, {"linenr": 449, "function": "_open", "line": "'_open', req)", "filename": "C:\\Python27\\lib\\urllib2.py"}, {"linenr": 409, "function": "_call_chain", "line": "result = func(*args)", "filename": "C:\\Python27\\lib\\urllib2.py"}, {"linenr": 1227, "function": "http_open", "line": "return self.do_open(httplib.HTTPConnection, req)", "filename": "C:\\Python27\\lib\\urllib2.py"}, {"linenr": 1197, "function": "do_open", "line": "raise URLError(err)", "filename": "C:\\Python27\\lib\\urllib2.py"}]}, "result": "error", "name": "test_login_password_ok_9___PA_13____login_senior_tester_firefox____luis____luis123____senior_tester____FIREFOX__"}], "nr_error": 10, "nr_success": 0, "name": "sanity_test.test_login.LoginTestClass", "nr_failed": 0}], "metadata": {"command": "C:\\Python27\\Scripts\\nosetests-script.py --with-json-extended -q -s test_login.py", "cwd": "D:\\Dropbox\\Dropbox\\positivo_selenium\\sanity_test", "time": 1449167811.714}}